<robot name = "robot">
    <link name="Main">
        <inertial>
            <origin xyz="0 0 3" rpy="0 0 0"/>
            <mass value="1" />
            <inertia ixx="100" ixy="0" ixz="0" iyy="100" iyz="0" izz="100" />
        </inertial>
        <visual>
            <origin xyz="0 0 3" rpy="0 0 0"/>
            <geometry>
                <box size="0.9564503022553775 1.5307886596461462 0.3523142851462786" />
            </geometry>
            <material name="Green">
                <color rgba="0.0 1.0 0.0 1.0"/>
            </material>
        </visual>
        <collision>
            <origin xyz="0 0 3" rpy="0 0 0"/>
            <geometry>
                <box size="0.9564503022553775 1.5307886596461462 0.3523142851462786" />
            </geometry>
        </collision>
    </link>
    <joint name="Main_Limb1" type="revolute">
       <parent link="Main"/>
       <child  link="Limb1"/>
       <origin rpy="0 0 0" xyz="0.47822515112768876 0.5102628865487154 2.8238428574268606" />
       <axis xyz="0 1 0"/>
       <limit effort="0.0" lower="-3.14159" upper="3.14159" velocity="0.0"/>
    </joint>
    <link name="Limb1">
        <inertial>
            <origin xyz="0.06460802553363876 0 -0.2680853504577515" rpy="0 0 0"/>
            <mass value="1" />
            <inertia ixx="100" ixy="0" ixz="0" iyy="100" iyz="0" izz="100" />
        </inertial>
        <visual>
            <origin xyz="0.06460802553363876 0 -0.2680853504577515" rpy="0 0 0"/>
            <geometry>
                <box size="0.12921605106727752 0.4718218055582394 0.536170700915503" />
            </geometry>
            <material name="Blue">
                <color rgba="0.0 0.0 1.0 1.0"/>
            </material>
        </visual>
        <collision>
            <origin xyz="0.06460802553363876 0 -0.2680853504577515" rpy="0 0 0"/>
            <geometry>
                <box size="0.12921605106727752 0.4718218055582394 0.536170700915503" />
            </geometry>
        </collision>
    </link>
    <joint name="Main_Limb2" type="revolute">
       <parent link="Main"/>
       <child  link="Limb2"/>
       <origin rpy="0 0 0" xyz="0.47822515112768876 -0.5102628865487154 2.8238428574268606" />
       <axis xyz="0 1 0"/>
       <limit effort="0.0" lower="-3.14159" upper="3.14159" velocity="0.0"/>
    </joint>
    <link name="Limb2">
        <inertial>
            <origin xyz="0.012255647702540284 0 -0.4748288751655688" rpy="0 0 0"/>
            <mass value="1" />
            <inertia ixx="100" ixy="0" ixz="0" iyy="100" iyz="0" izz="100" />
        </inertial>
        <visual>
            <origin xyz="0.012255647702540284 0 -0.4748288751655688" rpy="0 0 0"/>
            <geometry>
                <box size="0.02451129540508057 0.06186293439158508 0.9496577503311376" />
            </geometry>
            <material name="Blue">
                <color rgba="0.0 0.0 1.0 1.0"/>
            </material>
        </visual>
        <collision>
            <origin xyz="0.012255647702540284 0 -0.4748288751655688" rpy="0 0 0"/>
            <geometry>
                <box size="0.02451129540508057 0.06186293439158508 0.9496577503311376" />
            </geometry>
        </collision>
    </link>
    <joint name="Main_Limb3" type="revolute">
       <parent link="Main"/>
       <child  link="Limb3"/>
       <origin rpy="0 0 0" xyz="-0.47822515112768876 0.5102628865487154 2.8238428574268606" />
       <axis xyz="0 1 0"/>
       <limit effort="0.0" lower="-3.14159" upper="3.14159" velocity="0.0"/>
    </joint>
    <link name="Limb3">
        <inertial>
            <origin xyz="-0.273457358366521 0 -0.4035651206572261" rpy="0 0 0"/>
            <mass value="1" />
            <inertia ixx="100" ixy="0" ixz="0" iyy="100" iyz="0" izz="100" />
        </inertial>
        <visual>
            <origin xyz="-0.273457358366521 0 -0.4035651206572261" rpy="0 0 0"/>
            <geometry>
                <box size="0.546914716733042 0.8946989172932708 0.8071302413144522" />
            </geometry>
            <material name="Green">
                <color rgba="0.0 1.0 0.0 1.0"/>
            </material>
        </visual>
        <collision>
            <origin xyz="-0.273457358366521 0 -0.4035651206572261" rpy="0 0 0"/>
            <geometry>
                <box size="0.546914716733042 0.8946989172932708 0.8071302413144522" />
            </geometry>
        </collision>
    </link>
    <joint name="Main_Limb4" type="revolute">
       <parent link="Main"/>
       <child  link="Limb4"/>
       <origin rpy="0 0 0" xyz="-0.47822515112768876 -0.5102628865487154 2.8238428574268606" />
       <axis xyz="0 1 0"/>
       <limit effort="0.0" lower="-3.14159" upper="3.14159" velocity="0.0"/>
    </joint>
    <link name="Limb4">
        <inertial>
            <origin xyz="-0.2764816165310274 0 -0.2131879398264599" rpy="0 0 0"/>
            <mass value="1" />
            <inertia ixx="100" ixy="0" ixz="0" iyy="100" iyz="0" izz="100" />
        </inertial>
        <visual>
            <origin xyz="-0.2764816165310274 0 -0.2131879398264599" rpy="0 0 0"/>
            <geometry>
                <box size="0.5529632330620547 0.26761058107505276 0.4263758796529198" />
            </geometry>
            <material name="Blue">
                <color rgba="0.0 0.0 1.0 1.0"/>
            </material>
        </visual>
        <collision>
            <origin xyz="-0.2764816165310274 0 -0.2131879398264599" rpy="0 0 0"/>
            <geometry>
                <box size="0.5529632330620547 0.26761058107505276 0.4263758796529198" />
            </geometry>
        </collision>
    </link>
</robot>